ERROR:root:
Traceback (most recent call last):
  File "code.py", line 6, in <module>
    raise Exception
Exception
